Workbook

Sheet Final BOM
A1: Heli Collective - final BOM
A2: Everything bought for one collective: the HeliSR Rev 3.0 board (the bare PCB is ordered from OSH Park; every part on it comes from Digi-Key), the Huey head and the MkIII base Rev 3 (a concept, not yet printed). Blue line: already ordered. Green: covered by a kit or pack priced on another line. Orange: size taken from the base's CAD, not from a parts list, so check before ordering. Prices are pack prices: Digi-Key cart (2026-10-23), Amazon listings (2026-10-22 and 2026-10-23) and the OSH Park order, before shipping and tariff. The Digi-Key order sheet lists the electronics to order from Digi-Key.
A3: Collectives to build | C3: 1 | D3: Edit the yellow cells: collectives to build here, and Packs bought for anything you already have. Packs round up; lines marked once are one per order, however many you build.
A5: # | B5: Where | C5: Qty per collective | D5: Pack | E5: Packs needed | F5: Packs bought | G5: Packs to order | H5: Description | I5: Manufacturer | J5: Mfr part number | K5: Supplier | L5: Supplier part number | M5: Pack price | N5: To spend | O5: Notes | P5: Source
A6: HeliSR Rev 3.0: the parts you solder to the bare board (Digi-Key)
A7: 1 | B7: U1, U2 | C7: 2 | D7: 1 | E7: =ROUNDUP(C7*$C$3/D7,0) | F7: 2 | G7: =MAX(0,E7-F7) | H7: Shift register, 74HC165, SOIC-16 | I7: Texas Instruments | J7: SN74HC165DR | K7: Digi-Key | L7: 296-8250-1-ND | M7: 0.5 | N7: =IF(M7="","",G7*M7) | O7: Under the Pro Micro: fit before the sockets | P7: PCB/HeliSR_Rev3.0 board BOM (checked against the ordered board)
A8: 2 | B8: RN1, RN2 | C8: 2 | D8: 1 | E8: =ROUNDUP(C8*$C$3/D8,0) | F8: 2 | G8: =MAX(0,E8-F8) | H8: Resistor network, 8 x 10 kOhm bussed, SIP-9 | I8: Bourns | J8: 4609X-101-103LF | K8: Digi-Key | L8: 4609X-101-103LF-ND | M8: 0.39 | N8: =IF(M8="","",G8*M8) | O8: Pin 1 (dot) is the common pin: it goes in the square pad. Keep upright | P8: PCB/HeliSR_Rev3.0 board BOM (checked against the ordered board)
A9: 3 | B9: C1, C2 | C9: 2 | D9: 1 | E9: =ROUNDUP(C9*$C$3/D9,0) | F9: 2 | G9: =MAX(0,E9-F9) | H9: Capacitor, 100 nF, 50 V, X7R, 1206 | I9: Samsung | J9: CL31B104KBCNNNC | K9: Digi-Key | L9: 1276-1017-1-ND | M9: 0.14 | N9: =IF(M9="","",G9*M9) | O9: Decoupling: C1 beside U1's VCC pin, C2 beside U2's | P9: PCB/HeliSR_Rev3.0 board BOM (checked against the ordered board)
A10: 4 | B10: C3 | C10: 1 | D10: 1 | E10: =ROUNDUP(C10*$C$3/D10,0) | F10: 1 | G10: =MAX(0,E10-F10) | H10: Capacitor, 22 uF, 10 V, X5R, 1206 | I10: Samsung | J10: CL31A226KPHNNNE | K10: Digi-Key | L10: 1276-1287-1-ND | M10: 0.47 | N10: =IF(M10="","",G10*M10) | O10: Bulk supply capacitor, between U1 and U2 | P10: PCB/HeliSR_Rev3.0 board BOM (checked against the ordered board)
A11: 5 | B11: R1, R2 | C11: 2 | D11: 1 | E11: =ROUNDUP(C11*$C$3/D11,0) | F11: 2 | G11: =MAX(0,E11-F11) | H11: Resistor, 1 kOhm, 1 %, 1/8 W, 0805 | I11: YAGEO | J11: RC0805FR-071KL | K11: Digi-Key | L11: 311-1.00KCRCT-ND | M11: 0.1 | N11: =IF(M11="","",G11*M11) | O11: In series with PROG1 (R1) and PROG4 (R2) | P11: PCB/HeliSR_Rev3.0 board BOM (checked against the ordered board)
A12: 6 | B12: SW1-SW3 | C12: 3 | D12: 1 | E12: =ROUNDUP(C12*$C$3/D12,0) | F12: 3 | G12: =MAX(0,E12-F12) | H12: Tactile switch, SMD, 3.9 x 2.9 mm, gull wing | I12: E-Switch | J12: TL1015AF160QG | K12: Digi-Key | L12: EG4344CT-ND | M12: 0.48 | N12: =IF(M12="","",G12*M12) | O12: SW1 RST, SW2 PROG1 (AX1), SW3 PROG4 (AX4). The four ground tabs are left unsoldered | P12: PCB/HeliSR_Rev3.0 board BOM (checked against the ordered board)
A13: 7 | B13: J1, J2 | C13: 2 | D13: 1 | E13: =ROUNDUP(C13*$C$3/D13,0) | F13: 2 | G13: =MAX(0,E13-F13) | H13: JST SR/SH header, 10-pin, 1.0 mm, SMD, top entry | I13: JST | J13: BM10B-SRSS-TBT | K13: Digi-Key | L13: 455-BM10B-SRSS-TBTCT-ND | M13: 1.19 | N13: =IF(M13="","",G13*M13) | O13: Switch inputs: J1 IN1-IN8, J2 IN9-IN16. Digi-Key estimates $0.33 tariff each on top | P13: PCB/HeliSR_Rev3.0 board BOM (checked against the ordered board)
A14: 8 | B14: J11-J14 | C14: 4 | D14: 1 | E14: =ROUNDUP(C14*$C$3/D14,0) | F14: 4 | G14: =MAX(0,E14-F14) | H14: JST SR/SH header, 3-pin, 1.0 mm, SMD, top entry | I14: JST | J14: BM03B-SRSS-TBT | K14: Digi-Key | L14: 455-BM03B-SRSS-TBTCT-ND | M14: 0.68 | N14: =IF(M14="","",G14*M14) | O14: Analog inputs AX1-AX4 (J11-J14). Digi-Key estimates $0.26 tariff each on top. Fit all four, or only the inputs you use | P14: PCB/HeliSR_Rev3.0 board BOM (checked against the ordered board)
A15: 9 | B15: J7, J8 | C15: 2 | D15: 1 | E15: =ROUNDUP(C15*$C$3/D15,0) | F15: 2 | G15: =MAX(0,E15-F15) | H15: Socket header, female, 1x12, 2.54 mm, through hole | I15: Sullins | J15: PPTC121LFBN-RC | K15: Digi-Key | L15: S6100-ND | M15: 0.75 | N15: =IF(M15="","",G15*M15) | O15: Pro Micro sockets. Fit last | P15: PCB/HeliSR_Rev3.0 board BOM (checked against the ordered board)
M16: Subtotal | N16: =SUM(N7:N15)
A17: HeliSR Rev 3.0: bare PCB and controller
A18: 10 | B18: PCB | C18: 1 | D18: 3 | E18: =ROUNDUP(C18*$C$3/D18,0) | F18: 1 | G18: =MAX(0,E18-F18) | H18: HeliSR Rev 3.0 bare PCB (no parts fitted), 2 layers, 1.6 mm FR4, 39.3 x 33.64 mm | I18: OSH Park | K18: OSH Park | M18: 10.2 | N18: =IF(M18="","",G18*M18) | O18: Ordered 2026-10-21: $10.20 for three bare boards, free shipping, due back about 2026-10-29 | P18: OSH Park order confirmation
A19: 11 | B19: J7, J8 | C19: 1 | D19: 1 | E19: =ROUNDUP(C19*$C$3/D19,0) | F19: 1 | G19: =MAX(0,E19-F19) | H19: Pro Micro 5V/16 MHz (ATmega32U4), USB-C, with header pins | I19: OSOYOO | K19: Amazon | L19: B0B81FGBLY | M19: 11.99 | N19: =IF(M19="","",G19*M19) | O19: Runs MMJoy2; plugs into the J7/J8 sockets. Comes with three rows of header pins, so no separate headers. Also sold as 3 for $21.99. Check that its 2 x 12 pins line up with J7/J8 (15.24 mm between rows) | P19: Amazon listing on 2026-10-22 (link you sent)
M20: Subtotal | N20: =SUM(N18:N19)
A21: Wiring
A22: 12 | B22: J1, J2 | C22: 1 | D22: 1 | E22: =ROUNDUP(C22*$C$3/D22,0) | F22: 1 | G22: =MAX(0,E22-F22) | H22: JST SR jumper, 10-pin, 10 in, 30 AWG, pin 1 to pin 1 | I22: JST | J22: A10SR10SR30K254A | K22: Digi-Key | L22: 455-3671-ND | M22: 3.17 | N22: =IF(M22="","",G22*M22) | O22: Switch loom. The jumper has a connector at each end: cut it in half for the two board-end pigtails (J1 and J2). Price from Digi-Key, 2026-10-22 | P22: PCB/HeliSR_Rev3.0/HeliSR_Rev3.0_BOM.xlsx (Digi-Key cart)
A23: 13 | B23: J11, J14 | C23: 2 | D23: 1 | E23: =ROUNDUP(C23*$C$3/D23,0) | F23: 2 | G23: =MAX(0,E23-F23) | H23: JST SR jumper, 3-pin, 8 in, 30 AWG, pin 1 to pin 1 | I23: JST | J23: A03SR03SR30K203A | K23: Digi-Key | L23: 455-3627-ND | M23: 1.35 | N23: =IF(M23="","",G23*M23) | O23: AX1 (collective sensor) and AX4 (throttle sensor); AX2 and AX3 are spare. Price from Digi-Key, 2026-10-22 | P23: PCB/HeliSR_Rev3.0/HeliSR_Rev3.0_BOM.xlsx (Digi-Key cart)
A24: 14 | B24: AX1 lead | C24: 1 | D24: 1 | E24: =ROUNDUP(C24*$C$3/D24,0) | F24: 1 | G24: =MAX(0,E24-F24) | H24: 3-core cable, 28 AWG, black, 1 m (Digi-Key cut length) | I24: Tensility | J24: 30-01653 | K24: Digi-Key | L24: 839-30-01653-DS-ND | M24: 2.28 | N24: =IF(M24="","",G24*M24) | O24: CHECK: Collective sensor lead: from the AS5600 in the base, through the lever's cable channels and up the 470 mm tube, spliced to an AX1 pigtail. Length is an estimate: measure your run; Digi-Key sells it by the metre | P24: Digi-Key cart 2026-10-23; Base/README.md (the 3-core sensor lead)
A25: 15 | B25: USB | C25: 1 | D25: 1 | E25: =ROUNDUP(C25*$C$3/D25,0) | F25: 1 | G25: =MAX(0,E25-F25) | H25: USB 2.0 cable, USB-A plug to USB-C plug, 2 m (6.56 ft) | I25: Stewart Connector | J25: SC-2CAK020M | K25: Digi-Key | L25: 380-SC-2CAK020M-ND | M25: 7.33 | N25: =IF(M25="","",G25*M25) | O25: Cut it about 15 cm from the USB-C plug. Feed the long piece (USB-A end stays at the PC) through the device: laid in the lever's open channels, up the tube and in through the head. The cable cover's spout is a plain 7.5 mm bore. Splice the USB-C stub back on inside the head (red, black, green, white) and leave the shield wire unconnected. The cut costs about 15 cm of the 2 m: check the run still reaches. The head's clearances were checked with a micro-USB plug: check the C plug fits the same way | P25: Digi-Key cart 2026-10-23; Head/Rev4/README.md; Base/README.md
M26: Subtotal | N26: =SUM(N22:N25)
A27: Angle sensors
A28: 16 | B28: AX1, AX4 | C28: 2 | D28: 4 | E28: =ROUNDUP(C28*$C$3/D28,0) | F28: 1 | G28: =MAX(0,E28-F28) | H28: AS5600 magnetic encoder module, 23 x 23 mm, with 5 x 2 mm diametric magnet | I28: WWZMDiB | K28: Amazon | L28: B0CM3C8KFT | M28: 9.99 | N28: =IF(M28="","",G28*M28) | O28: Sold in fours. AX1: the collective, in the base, programmed with PROG1, DIR to VCC. AX4: the throttle, in the head, programmed with PROG4, DIR to GND. On each: remove the 0 ohm R1, keep R4 | P28: Amazon listing on 2026-10-22 (link you sent)
M29: Subtotal | N29: =SUM(N28:N28)
A30: Huey head: switches
A31: 17 | B31: IN3-IN6 | C31: 2 | D31: 1 | E31: =ROUNDUP(C31*$C$3/D31,0) | F31: 2 | G31: =MAX(0,E31-F31) | H31: Toggle switch, SPDT, ON-OFF-ON, M12 bushing, solder lug | I31: APEM | J31: 639H/2 | K31: Digi-Key | L31: 679-1223-ND | M31: 8.47 | N31: =IF(M31="","",G31*M31) | O31: LDG LT EXT / RETR and SL ON / STOW. Common to GND. Price from Digi-Key, 2026-10-22 | P31: PCB/HeliSR_Rev3.0/HeliSR_Rev3.0_BOM.xlsx (Digi-Key cart)
A32: 18 | B32: IN1, IN2 | C32: 1 | D32: 1 | E32: =ROUNDUP(C32*$C$3/D32,0) | F32: 1 | G32: =MAX(0,E32-F32) | H32: Toggle switch, SPDT, (ON)-OFF-(ON), M12 bushing, solder lug | I32: APEM | J32: 637H/2 | K32: Digi-Key | L32: 679-1219-ND | M32: 8.02 | N32: =IF(M32="","",G32*M32) | O32: GOV RPM INCR / DECR. Price from Digi-Key, 2026-10-22 | P32: PCB/HeliSR_Rev3.0/HeliSR_Rev3.0_BOM.xlsx (Digi-Key cart)
A33: 19 | B33: IN7 | C33: 1 | D33: 1 | E33: =ROUNDUP(C33*$C$3/D33,0) | F33: 1 | G33: =MAX(0,E33-F33) | H33: Toggle switch, SPDT, ON-ON, M12 bushing, solder lug | I33: APEM | J33: 636H/2 | K33: Digi-Key | L33: 679-1217-ND | M33: 7.55 | N33: =IF(M33="","",G33*M33) | O33: LDG LT ON (one side wired). Price from Digi-Key, 2026-10-22 | P33: PCB/HeliSR_Rev3.0/HeliSR_Rev3.0_BOM.xlsx (Digi-Key cart)
A34: 20 | B34: IN13 | C34: 1 | D34: 1 | E34: =ROUNDUP(C34*$C$3/D34,0) | F34: 1 | G34: =MAX(0,E34-F34) | H34: Push button, large, SPST-NO momentary, M12 | I34: Same Sky | J34: PB4-M-BK-D-67 | K34: Digi-Key | L34: 2223-PB4-M-BK-D-67-ND | M34: 2.52 | N34: =IF(M34="","",G34*M34) | O34: STOP REL | P34: PCB/HeliSR_Rev3.0/HeliSR_Rev3.0_BOM.xlsx (Digi-Key cart)
A35: 21 | B35: IN9-IN12, IN14 | C35: 5 | D35: 1 | E35: =ROUNDUP(C35*$C$3/D35,0) | F35: 5 | G35: =MAX(0,E35-F35) | H35: Tactile switch, 6 x 6 mm, 5 mm high, THT | I35: TE Connectivity | J35: 1825910-6 | K35: Digi-Key | L35: 450-1650-ND | M35: 0.13 | N35: =IF(M35="","",G35*M35) | O35: SEARCH CONT hat (4) and starter trigger (1). IN8, IN15, IN16 are spare | P35: PCB/HeliSR_Rev3.0/HeliSR_Rev3.0_BOM.xlsx (Digi-Key cart)
M36: Subtotal | N36: =SUM(N31:N35)
A37: Huey head: hardware
A38: 22 | B38: Tube boss | C38: 1 | D38: 1 | E38: =ROUNDUP(C38*$C$3/D38,0) | F38: 0 | G38: =MAX(0,E38-F38) | H38: M5 x 8 set screw | I38: HIQTRADEBYJJ | K38: Amazon | L38: B0DG33R714 | M38: 0 | N38: =IF(M38="","",G38*M38) | O38: In the set screw kit. From the boss's front (lower panel off): tap the 4.2 mm pilot M5; the tip pins the tube through the front wall of its 5.2 mm cross hole, 10 mm below the tube's top. Replaces the M5 x 40 bolt and nut (the kit's M5s stop at 20 mm) | P38: HIQTRADEBYJJ set screw kit (Amazon B0DG33R714); Head/Rev4 and Base/mk3_rev3.py screw lists; renders/*Screws*.png
A39: 23 | B39: Friction collar | C39: 1 | D39: 1 | E39: =ROUNDUP(C39*$C$3/D39,0) | F39: 0 | G39: =MAX(0,E39-F39) | H39: M4 x 12 countersunk screw + M4 hex nut | I39: AvrestYPT | K39: Amazon | L39: B0FMD5TMSH | M39: 0 | N39: =IF(M39="","",G39*M39) | O39: In the screw kit. Pinch screw: the head sits 2 mm into the +y ear, the nut in the -y ear's pocket | P39: AvrestYPT screw kit (Amazon B0FMD5TMSH); Head/Rev4 and Base/mk3_rev3.py screw lists; renders/*Screws*.png
A40: 24 | B40: Throttle grip | C40: 4 | D40: 50 | E40: =ROUNDUP(C40*$C$3/D40,0) | F40: 1 | G40: =MAX(0,E40-F40) | H40: O-ring, 24 mm ID x 28 mm OD x 2 mm, nitrile (NBR 70A), pack of 50 | I40: FOCMKEAS | K40: Amazon | L40: B0BWWBTL4N | M40: 6.89 | N40: =IF(M40="","",G40*M40) | O40: The grip floats on these: two in grooves in its bore (its bearings on the tube), one in the friction collar's groove and one in the ceiling's groove round the tube. Grease them lightly with silicone grease | P40: Head/Rev4/README.md and Head/Rev3/README.md, Bought; Amazon listing 2026-10-23
A41: 25 | B41: Trigger pivot | C41: 1 | D41: once | E41: =IF($C$3>0,C41,0) | F41: 1 | G41: =MAX(0,E41-F41) | H41: M3 countersunk hex socket screws, 10.9 black oxide, M3 x 20 / 25 / 30 / 35 / 40, 100 pcs | I41: Amazon | K41: Amazon | L41: B0BYXS4BTF | M41: 9.99 | N41: =IF(M41="","",G41*M41) | O41: Ordered 2026-10-23. Uses the M3 x 25 (ISO 10642 / DIN 7991); the kits stop at 20 mm. Head in the countersink in the mount's left lug, through the trigger, then about 8 mm into the right lug's 2.5 mm pilot (tap it M3 all the way through); the tip stays about 0.9 mm inside the lug | P41: Head/Rev4/README.md and Head/Rev3/README.md, Bought; user's choice 2026-10-23; Amazon listing 2026-10-23
...

Sheet Digi-Key order
A1: Heli Collective - Digi-Key order
A2: Every line to buy from Digi-Key. Quantities come from the Final BOM's Packs to order, so they follow the collectives to build and anything marked as bought. Heli_Collective_DigiKey.csv holds the same order for one collective (part number, quantity, customer reference), for Digi-Key's cart or BOM upload.
A4: # | B4: Digi-Key part number | C4: Quantity | D4: Mfr part number | E4: Description | F4: Customer reference | G4: Unit price | H4: Ext. price | I4: Notes
A5: 1 | B5: 296-8250-1-ND | C5: ='Final BOM'!G7 | D5: SN74HC165DR | E5: Shift register, 74HC165, SOIC-16 | F5: U1, U2 | G5: ='Final BOM'!M7 | H5: =IF('Final BOM'!M7="","",C5*G5) | I5: Under the Pro Micro: fit before the sockets
A6: 2 | B6: 4609X-101-103LF-ND | C6: ='Final BOM'!G8 | D6: 4609X-101-103LF | E6: Resistor network, 8 x 10 kOhm bussed, SIP-9 | F6: RN1, RN2 | G6: ='Final BOM'!M8 | H6: =IF('Final BOM'!M8="","",C6*G6) | I6: Pin 1 (dot) is the common pin: it goes in the square pad. Keep upright
A7: 3 | B7: 1276-1017-1-ND | C7: ='Final BOM'!G9 | D7: CL31B104KBCNNNC | E7: Capacitor, 100 nF, 50 V, X7R, 1206 | F7: C1, C2 | G7: ='Final BOM'!M9 | H7: =IF('Final BOM'!M9="","",C7*G7) | I7: Decoupling: C1 beside U1's VCC pin, C2 beside U2's
A8: 4 | B8: 1276-1287-1-ND | C8: ='Final BOM'!G10 | D8: CL31A226KPHNNNE | E8: Capacitor, 22 uF, 10 V, X5R, 1206 | F8: C3 | G8: ='Final BOM'!M10 | H8: =IF('Final BOM'!M10="","",C8*G8) | I8: Bulk supply capacitor, between U1 and U2
A9: 5 | B9: 311-1.00KCRCT-ND | C9: ='Final BOM'!G11 | D9: RC0805FR-071KL | E9: Resistor, 1 kOhm, 1 %, 1/8 W, 0805 | F9: R1, R2 | G9: ='Final BOM'!M11 | H9: =IF('Final BOM'!M11="","",C9*G9) | I9: In series with PROG1 (R1) and PROG4 (R2)
A10: 6 | B10: EG4344CT-ND | C10: ='Final BOM'!G12 | D10: TL1015AF160QG | E10: Tactile switch, SMD, 3.9 x 2.9 mm, gull wing | F10: SW1-SW3 | G10: ='Final BOM'!M12 | H10: =IF('Final BOM'!M12="","",C10*G10) | I10: SW1 RST, SW2 PROG1 (AX1), SW3 PROG4 (AX4). The four ground tabs are left unsoldered
A11: 7 | B11: 455-BM10B-SRSS-TBTCT-ND | C11: ='Final BOM'!G13 | D11: BM10B-SRSS-TBT | E11: JST SR/SH header, 10-pin, 1.0 mm, SMD, top entry | F11: J1, J2 | G11: ='Final BOM'!M13 | H11: =IF('Final BOM'!M13="","",C11*G11) | I11: Switch inputs: J1 IN1-IN8, J2 IN9-IN16. Digi-Key estimates $0.33 tariff each on top
A12: 8 | B12: 455-BM03B-SRSS-TBTCT-ND | C12: ='Final BOM'!G14 | D12: BM03B-SRSS-TBT | E12: JST SR/SH header, 3-pin, 1.0 mm, SMD, top entry | F12: J11-J14 | G12: ='Final BOM'!M14 | H12: =IF('Final BOM'!M14="","",C12*G12) | I12: Analog inputs AX1-AX4 (J11-J14). Digi-Key estimates $0.26 tariff each on top. Fit all four, or only the inputs you use
A13: 9 | B13: S6100-ND | C13: ='Final BOM'!G15 | D13: PPTC121LFBN-RC | E13: Socket header, female, 1x12, 2.54 mm, through hole | F13: J7, J8 | G13: ='Final BOM'!M15 | H13: =IF('Final BOM'!M15="","",C13*G13) | I13: Pro Micro sockets. Fit last
A14: 10 | B14: 455-3671-ND | C14: ='Final BOM'!G22 | D14: A10SR10SR30K254A | E14: JST SR jumper, 10-pin, 10 in, 30 AWG, pin 1 to pin 1 | F14: J1, J2 | G14: ='Final BOM'!M22 | H14: =IF('Final BOM'!M22="","",C14*G14) | I14: Switch loom. The jumper has a connector at each end: cut it in half for the two board-end pigtails (J1 and J2). Price from Digi-Key, 2026-10-22
A15: 11 | B15: 455-3627-ND | C15: ='Final BOM'!G23 | D15: A03SR03SR30K203A | E15: JST SR jumper, 3-pin, 8 in, 30 AWG, pin 1 to pin 1 | F15: J11, J14 | G15: ='Final BOM'!M23 | H15: =IF('Final BOM'!M23="","",C15*G15) | I15: AX1 (collective sensor) and AX4 (throttle sensor); AX2 and AX3 are spare. Price from Digi-Key, 2026-10-22
A16: 12 | B16: 839-30-01653-DS-ND | C16: ='Final BOM'!G24 | D16: 30-01653 | E16: 3-core cable, 28 AWG, black, 1 m (Digi-Key cut length) | F16: AX1 lead | G16: ='Final BOM'!M24 | H16: =IF('Final BOM'!M24="","",C16*G16) | I16: Collective sensor lead: from the AS5600 in the base, through the lever's cable channels and up the 470 mm tube, spliced to an AX1 pigtail. Length is an estimate: measure your run; Digi-Key sells it by the metre
A17: 13 | B17: 380-SC-2CAK020M-ND | C17: ='Final BOM'!G25 | D17: SC-2CAK020M | E17: USB 2.0 cable, USB-A plug to USB-C plug, 2 m (6.56 ft) | F17: USB | G17: ='Final BOM'!M25 | H17: =IF('Final BOM'!M25="","",C17*G17) | I17: Cut it about 15 cm from the USB-C plug. Feed the long piece (USB-A end stays at the PC) through the device: laid in the lever's open channels, up the tube and in through the head. The cable cover's spout is a plain 7.5 mm bore. Splice the USB-C stub back on inside the head (red, black, green, white) and leave the shield wire unconnected. The cut costs about 15 cm of the 2 m: check the run still reaches. The head's clearances were checked with a micro-USB plug: check the C plug fits the same way
A18: 14 | B18: 679-1223-ND | C18: ='Final BOM'!G31 | D18: 639H/2 | E18: Toggle switch, SPDT, ON-OFF-ON, M12 bushing, solder lug | F18: IN3-IN6 | G18: ='Final BOM'!M31 | H18: =IF('Final BOM'!M31="","",C18*G18) | I18: LDG LT EXT / RETR and SL ON / STOW. Common to GND. Price from Digi-Key, 2026-10-22
A19: 15 | B19: 679-1219-ND | C19: ='Final BOM'!G32 | D19: 637H/2 | E19: Toggle switch, SPDT, (ON)-OFF-(ON), M12 bushing, solder lug | F19: IN1, IN2 | G19: ='Final BOM'!M32 | H19: =IF('Final BOM'!M32="","",C19*G19) | I19: GOV RPM INCR / DECR. Price from Digi-Key, 2026-10-22
A20: 16 | B20: 679-1217-ND | C20: ='Final BOM'!G33 | D20: 636H/2 | E20: Toggle switch, SPDT, ON-ON, M12 bushing, solder lug | F20: IN7 | G20: ='Final BOM'!M33 | H20: =IF('Final BOM'!M33="","",C20*G20) | I20: LDG LT ON (one side wired). Price from Digi-Key, 2026-10-22
A21: 17 | B21: 2223-PB4-M-BK-D-67-ND | C21: ='Final BOM'!G34 | D21: PB4-M-BK-D-67 | E21: Push button, large, SPST-NO momentary, M12 | F21: IN13 | G21: ='Final BOM'!M34 | H21: =IF('Final BOM'!M34="","",C21*G21) | I21: STOP REL
A22: 18 | B22: 450-1650-ND | C22: ='Final BOM'!G35 | D22: 1825910-6 | E22: Tactile switch, 6 x 6 mm, 5 mm high, THT | F22: IN9-IN12, IN14 | G22: ='Final BOM'!M35 | H22: =IF('Final BOM'!M35="","",C22*G22) | I22: SEARCH CONT hat (4) and starter trigger (1). IN8, IN15, IN16 are spare
A23: 19 | B23: SRS-4-4MM-ND | C23: ='Final BOM'!G45 | D23: SRS-4-4MM | E23: Round spacer, unthreaded, for M3, 4 mm long, 6.4 mm OD, PVC, self-retaining | F23: HeliSR board | G23: ='Final BOM'!M45 | H23: =IF('Final BOM'!M45="","",C23*G23) | I23: Between the rear wall and the board
A24: 20 | B24: 315-NC191LT10-ND | C24: ='Final BOM'!G69 | D24: NC191LT10 | E24: Solder paste, low-temperature (Sn42/Bi58, 138 C), syringe | F24: Assembly | G24: ='Final BOM'!M69 | H24: =IF('Final BOM'!M69="","",C24*G24) | I24: For the SMD parts on the board (U1, U2, the 1206 caps, the JST headers, SW1-SW3). Needs a hot plate or hot air tool and flux. Optional: hand-soldering works too
A25: 21 | B25: 1188-CHN-TWZ1MM-ND | C25: ='Final BOM'!G70 | D25: CHN-TWZ1MM | E25: Tweezers, 1 mm tip (Olimex CHN-TWZ1MM), for placing the SMD parts | F25: Assembly | G25: ='Final BOM'!M70 | H25: =IF('Final BOM'!M70="","",C25*G25) | I25: Description from Olimex's sibling CHN-TWZ2MM listing: check the tip
G26: Total | H26: =SUM(H5:H25)
A27: All 21 Digi-Key lines are priced (checked 2026-10-23), before shipping and tariff.

Sheet Printed parts
A1: Heli Collective - printed parts
A2: The print set for the Huey head and the MkIII base Rev 3, with the orientation each README gives. Print the coupons first. Paths are from the repository root.
A4: # | B4: Assembly | C4: File | D4: Qty | E4: Print
A5: 1 | B5: Head | C5: Head/Rev4/stl/HueyHeadR4-GripBearingCoupons.stl | D5: 1 | E5: Flat, labels up. Optional: checks the head's 25.2 mm tube bore on the carbon tube (the grip now rides on O-rings)
A6: 2 | B6: Head | C6: Head/Rev4/stl/HueyHeadR4-ORingCoupon.stl | D6: 1 | E6: Upright. A slice of the grip's bore with one O-ring groove: fit a greased 24 x 2 O-ring and slide it on the carbon tube before printing the grip (about 2 g)
A7: 3 | B7: Head | C7: Head/Rev4/stl/HueyHeadR4-SensorSeatCoupon.stl | D7: 1 | E7: The same way round as in the head on its rear wall. Optional: slide the AS5600 module through it first
A8: 4 | B8: Head | C8: Head/Rev4/stl/HueyHeadR4-Body.stl | D8: 1 | E8: One piece: box, neck, faux friction knob, boss, sensor pod and trigger mount. On its rear wall, with tree supports under the neck, knob and tube bore; then ream the bore to a press fit on the tube
A9: 5 | B9: Head | C9: Head/Rev4/stl/HueyHeadR4-LowerPanel-Black.stl + -WhiteText.stl | D9: 1 | E9: Front face down, two colours
A10: 6 | B10: Head | C10: Head/Rev4/stl/HueyHeadR4-UpperPanel-Black.stl + -WhiteText.stl | D10: 1 | E10: Front face down, two colours
A11: 7 | B11: Head | C11: Head/Rev4/stl/HueyHeadR4-Trigger.stl | D11: 1 | E11: On either flat side
A12: 8 | B12: Head | C12: Head/Rev4/stl/HueyHeadR4-SearchHat.stl | D12: 1 | E12: On its flat bottom ring
A13: 9 | B13: Head | C13: MkII original: 4way_Cover.stl, Bezel.stl, StickRetainer.stl, one ThumbStick-*.stl | D13: 1 | E13: The 4-way hat's parts, from the Thingiverse 5226353 head files (not in this folder). The ThumbStick comes in 4.5 to 5.8 mm, set by the switch's height: the TE 1825910-6 is 5.0 mm to the top of its button (datasheet), so print the 4.8 and the 5.3 and keep the one that clicks cleanly with no preload
A14: 10 | B14: Head | C14: Head/Rev4/stl/HueyHeadR4-ThrottleGrip.stl | D14: 1 | E14: Upright, bottom end down; no supports
A15: 11 | B15: Head | C15: Head/Rev4/stl/HueyHeadR4-FrictionCollar.stl | D15: 1 | E15: Bottom face down, O-ring groove up
A16: 12 | B16: Head | C16: Head/Rev4/stl/HueyHeadR4-Pinion.stl | D16: 1 | E16: Flat; the magnet shaft presses into its hex
... A24: 20 | B24: Base | C24: Base/stl/cable_plug.stl | D24: 1 | E24: On a long flat face. Fills the cable cover's slot once the USB cable is in
A25: 21 | B25: Base | C25: Base/stl/sensor_carrier.stl | D25: 1
A26: 22 | B26: Base | C26: Base/stl/shoe.stl | D26: 1
A27: 23 | B27: Base | C27: Base/stl/strut_collar.stl | D27: 1 | E27: Standing on one end
A28: 24 | B28: Base | C28: Base/stl/friction_knob.stl | D28: 1 | E28: Top face down; glue the M5 x 20's head into it

Sheet Dropped
A1: Heli Collective - dropped from earlier BOMs
A2: Lines in the Rev 3.0 board's full BOM, the Digi-Key cart or earlier head and base revisions that this build doesn't use. Take them out of the cart if they're still in it.
A4: # | B4: Item | C4: Qty | D4: Why | E4: Was in
A5: 1 | B5: Glue, thread-lock, taps, drill bit, felt tape, hose clamp, 10 mm spring, #10 desk screws | D5: You supply these yourself | E5: User, 2026-10-23
A6: 2 | B6: Fgruh M3 and M4 socket-cap screw kits, M3 x 10 / M4 x 30 / M5 x 40 countersunk packs, M6 x 25 and M6 x 30 bolts, M6 and M4 nyloc nuts, uxcell M5 x 5 set screws, heat-set inserts and insert tips | D6: Every screw and nut now comes from the AvrestYPT and set screw kits (2026-10-23): the CAD was changed to suit them | E6: User, 2026-10-23
A7: 3 | B7: MkII-AdjustKnob.stl (friction knob) | C7: 1 | D7: Took an M6 hex head; the base now prints its own knob for the M5 x 20 | E7: Base/mk3_pivot.py
A8: 4 | B8: SparkFun Pro Micro 12640 (Digi-Key 1568-12640-ND) | C8: 1 | D8: Replaced by the OSOYOO USB-C Pro Micro from Amazon | E8: PCB/HeliSR_Rev3.0/HeliSR_Rev3.0_BOM.xlsx (Digi-Key cart)
A9: 5 | B9: Sullins PRPC012SAAN-RC male headers (Digi-Key 35-PRPC012SAAN-RC-ND) | C9: 2 | D9: The OSOYOO Pro Micro comes with header pins | E9: PCB/HeliSR_Rev3.0/HeliSR_Rev3.0_BOM.xlsx (Digi-Key cart)
A10: 6 | B10: Assmann AK67421-2 USB A to micro-B cable | C10: 1 | D10: The OSOYOO Pro Micro is USB-C | E10: PCB/HeliSR_Rev3.0/HeliSR_Rev3.0_BOM.xlsx (Digi-Key cart)
A11: 7 | B11: E-Switch PS1024ABLK push button (EG2011-ND) | C11: 2 | D11: The head removed the two lower-panel push buttons | E11: PCB/HeliSR_Rev3.0/HeliSR_Rev3.0_BOM.xlsx (Digi-Key cart)
A12: 8 | B12: TT P0915N-QC20BR5K 5 k pot (987-1278-ND) | C12: 2 | D12: No head-knob pot any more; the throttle is read by an AS5600 | E12: PCB/HeliSR_Rev3.0/HeliSR_Rev3.0_BOM.xlsx (Digi-Key cart)
A13: 9 | B13: Knob for a 6 mm knurled shaft (Cliff FC7257) | C13: 1 | D13: Went with the head-knob pot | E13: PCB/HeliSR_Rev3.0/HeliSR_Rev3.0_BOM.xlsx (Digi-Key cart)
A14: 10 | B14: TI DRV5055A4 / A2 Hall sensors, KEMET axial 100 nF | C14: 3 | D14: MkII base only; the MkIII base uses an AS5600 | E14: PCB/HeliSR_Rev3.0/HeliSR_Rev3.0_BOM.xlsx (Digi-Key cart)
A15: 11 | B15: APEM MJTP1230A / G / F tactile switches (Digi-Key 679-2429-ND, 679-2435-ND, 679-2434-ND) | C15: 3 | D15: The TE 1825910-6 covers all five tactile inputs | E15: Digi-Key cart, 2026-10-22
A16: 12 | B16: Keystone 941 micro-B plug (Digi-Key 36-941-ND) | C16: 1 | D16: The Pro Micro is USB-C | E16: Digi-Key cart, 2026-10-22
A17: 13 | B17: Samsung CL10B104KB8WPNC 0.1 uF 0603 cap (Digi-Key 1276-6854-1-ND) | C17: 1 | D17: The board uses 1206 caps | E17: Digi-Key cart, 2026-10-22
A18: 14 | B18: Qualtek 3021017-10 USB-A to open-end cable, 10 ft (Digi-Key Q369-ND) | C18: 1 | D18: The Stewart A-to-C cable, cut and spliced, replaces it | E18: Digi-Key cart, 2026-10-22
... A21: 17 | B21: JST SR 3-pin jumpers beyond 2 | C21: 2 | D21: The full BOM had 4 (one per AX connector); only AX1 and AX4 are wired now | E21: PCB/HeliSR_Rev3.0/HeliSR_Rev3.0_BOM.xlsx (Digi-Key cart)
A22: 18 | B22: JST BM03B-SRSS-TBT: the cart has 3 | D22: A note, not dropped: the board has 4 footprints (J11-J14); this BOM orders 4 | E22: Digi-Key cart, 2026-10-22
A23: 19 | B23: MkII collective hardware (base, head bolts, springs, magnets) | D23: The MkII base is replaced by the MkIII Rev 3 | E23: HeliSR_Rev3.0_BOM.xlsx, sheet 2
A24: 20 | B24: 25 x 1 mm aluminium tube, 358 mm | C24: 1 | D24: Replaced by the base's 470 mm carbon tube | E24: Head/README.md (before)
A25: 21 | B25: Ballast bucket, lid, ~0.95 kg ballast, 4 x M4 bucket bolts + inserts, lid M3 screws + inserts | D25: Base Rev 3 balances with the gas strut | E25: Base/README.md, Bought parts
A26: 22 | B26: Quadrant stop block, thumb knob, M5 x 16 stop bolt + nut, M6 striker + insert | D26: Base Rev 3 has a fixed 32 deg stop | E26: Base/README.md, Bought parts
A27: 23 | B27: Rev 1 centre down-stop screw, nut and insert | D27: Base Rev 3 uses two down-stop posts beside the strut | E27: Base/mk3_rev3.py

Sheet Sources
A1: Heli Collective - sources
A2: Where each part of this BOM comes from. Regenerate with BOM/make_final_bom.py.
A4: Part | B4: Folder or document | C4: Status
A5: HeliSR Rev 3.0 board | B5: PCB/HeliSR_Rev3.0 | C5: Bare PCB ordered from OSH Park on 2026-10-21; folder frozen and read-only
A6: Huey head | B6: Head/Rev4 | C6: Current head design: Rev 4, one piece (Rev 3 with its neck block and trigger mount built back into the box). Rev 3 (Head/Rev3) is the same head in three parts, with no supports; Rev 2 (Head/) is superseded
A7: MkIII base Rev 3 | B7: Base (Base/mk3_rev3.py imports Base/mk3_pivot.py) | C7: Concept, nothing printed yet: check the orange lines
A8: Prices | B8: Digi-Key cart 2026-10-19 (JST headers 2026-10-22); Amazon listings 2026-10-22; OSH Park order 2026-10-21 | C8: Pack prices, before shipping and tariff
